Workbook

Sheet Read Me
A1: Centience partner referral contacts
A2: Source: Apollo.io people search + bulk enrichment, August 2026. 183 credits. Zero missing records across four waves.
A3: Built from partner-referral-contacts-ALL.csv in docs/marketing/. Strategy, commission tiers and legal guardrails live in partner-referral-program.md.
A5: Sheets
A6: Summary — counts by tier and email status. All formulas over All Contacts.
A7: All Contacts — every one of the 170 rows. Filter/sort freely; the Summary follows.
A8: Send List — one contact per firm (93 rows). This is the real campaign size, not 170.
A10: Fill these in (yellow cells on Send List)
A11: Owner · Status · Date contacted · Notes are blank for you. Nothing else needs editing.
A12: Example row: Owner "Orville" · Status "Replied — call booked" · Date contacted 2026-08-11 · Notes "Wants co-branded Score for 2 clients"
A14: Before you send
A15: ONE FIRM IS ONE RELATIONSHIP. "Contacts at firm" > 1 means alternates exist; they are fallbacks, not extra targets. Emailing three founding principals at one firm in a week reads as a scrape.
... A29: The Summary tab is formula-driven. This file was written by a script, so formula cells hold no cached value until Excel opens and calculates them — that happens automatically on open, and every function used (COUNTA, COUNTIF, SUMPRODUCT, SUM) is standard. Expected results are printed beside each figure on Summary so a wrong number is obvious.

Sheet Summary
A1: Centience partner referral list — summary
A2: All figures are formulas over the All Contacts sheet; they update if you edit or filter that data.
A4: Metric | B4: Count
A5: Contacts | B5: =COUNTA('All Contacts'!B2:B171) | D5: Expected: 170
A6: Distinct firms | B6: =SUMPRODUCT((('All Contacts'!D2:D171<>"")/COUNTIF('All Contacts'!D2:D171,'All Contacts'!D2:D171&""))) | D6: Expected: 93
A7: LinkedIn profiles | B7: =COUNTA('All Contacts'!I2:I171) | D7: Expected: 170
A8: Verified email | B8: =COUNTIF('All Contacts'!H2:H171,"verified") | D8: Expected: 152
A9: Guessed email (extrapolated) | B9: =COUNTIF('All Contacts'!H2:H171,"extrapolated") | D9: Expected: 2
A10: No email — LinkedIn only | B10: =COUNTIF('All Contacts'!H2:H171,"unavailable") | D10: Expected: 16
A11: Send List rows (1 per firm) | B11: =COUNTA('Send List'!B2:B94) | D11: Expected: 93
A13: Tier | B13: Contacts | C13: Firms
A14: Boutique compliance | B14: =COUNTIF('All Contacts'!A2:A171,A14) | C14: =COUNTIF('Send List'!A2:A94,A14)
A15: Compliance (national) | B15: =COUNTIF('All Contacts'!A2:A171,A15) | C15: =COUNTIF('Send List'!A2:A94,A15)
A16: Enterprise compliance | B16: =COUNTIF('All Contacts'!A2:A171,A16) | C16: =COUNTIF('Send List'!A2:A94,A16)
A17: Compliance + legal | B17: =COUNTIF('All Contacts'!A2:A171,A17) | C17: =COUNTIF('Send List'!A2:A94,A17)
A18: Cyber / E&O broker | B18: =COUNTIF('All Contacts'!A2:A171,A18) | C18: =COUNTIF('Send List'!A2:A94,A18)
A19: RIA platform | B19: =COUNTIF('All Contacts'!A2:A171,A19) | C19: =COUNTIF('Send List'!A2:A94,A19)
A20: Fund administrator | B20: =COUNTIF('All Contacts'!A2:A171,A20) | C20: =COUNTIF('Send List'!A2:A94,A20)
A21: RIA M&A advisor | B21: =COUNTIF('All Contacts'!A2:A171,A21) | C21: =COUNTIF('Send List'!A2:A94,A21)
A22: Securities counsel | B22: =COUNTIF('All Contacts'!A2:A171,A22) | C22: =COUNTIF('Send List'!A2:A94,A22)
A23: Adjacent / weaker fit | B23: =COUNTIF('All Contacts'!A2:A171,A23) | C23: =COUNTIF('Send List'!A2:A94,A23)
A24: Total | B24: =SUM(B14:B23) | C24: =SUM(C14:C23)
A26: Cells B5:C24 are formulas. Excel computes them the moment you open this file. If any figure differs from the "Expected" note beside it, the sheet was filtered or edited — recheck before relying on it.

Sheet All Contacts
A1: Tier | B1: Name | C1: Title | D1: Firm | E1: Contacts at firm | F1: Firm domain | G1: Work email | H1: Email status | I1: LinkedIn profile | J1: Location | K1: Firm phone | L1: Wave | M1: Apollo person ID
A2: Boutique compliance | B2: Vick Ekizian | C2: Founder and CEO | D2: 5 Pillars Compliance Consulting, LLC | E2: 1 | F2: 5pillarscompliance.com | G2: vick@5pillarscompliance.com | H2: verified | I2: /in/vickekizian | J2: Los Angeles California | K2: +1 818-523-9762 | L2: 1 | M2: 55706c157369646bf4db1500
A3: Boutique compliance | B3: Lisa Roitman | C3: Managing Partner | D3: Abide Consulting Group | E3: 3 | F3: abidegrp.com | G3: lisa@abidegrp.com | H3: verified | I3: /in/lisaroitman | J3: New York New York | K3: +1 212-362-4598 | L3: 1 | M3: 600f16e2bc34ca00016944cf
A4: Boutique compliance | B4: Patrick Harris | C4: Managing Director | D4: Abide Consulting Group | E4: 3 | F4: abidegrp.com | H4: unavailable | I4: /in/patrickeharris | J4: New York New York | K4: +1 212-362-4598 | L4: 2 | M4: 57dbbfc8a6da9868dafa2010
A5: Boutique compliance | B5: Pete Galloway | C5: Managing Partner | D5: Abide Consulting Group | E5: 3 | F5: abidegrp.com | G5: pete@abidegrp.com | H5: verified | I5: /in/petegalloway | J5: Denver Colorado | K5: +1 212-362-4598 | L5: 1 | M5: 54a48b1c7468692abf729a4f
A6: Boutique compliance | B6: Robert Masi | C6: Managing Partner | D6: Accordo | E6: 1 | F6: accordo.solutions | G6: robert.masi@accordo.solutions | H6: verified | I6: /in/robert-masi-1a123b8 | J6: New York New York | K6: +1 646-868-8150 | L6: 2 | M6: 66ed6833f501800001ee423f
A7: Boutique compliance | B7: Giselle Casella | C7: Vice President and Partner | D7: Adviser Compliance Consulting | E7: 2 | F7: outsourcecco.com | G7: gcasella@outsourcecco.com | H7: verified | I7: /in/giselle-casella-62090310 | J7: Naples Florida | K7: +1 650-703-2159 | L7: 1 | M7: 67000b23fd887b0001345983
A8: Boutique compliance | B8: Stephen Lurie | C8: Principal Owner | D8: Adviser Compliance Consulting | E8: 2 | F8: outsourcecco.com | H8: unavailable | I8: /in/stephen-lurie-8b0b371 | J8: New York New York | K8: +1 650-703-2159 | L8: 1 | M8: 610a381ea614ea00018458e2
A9: Boutique compliance | B9: Joseph Stowell | C9: Managing Partner, President | D9: Ally Compliance Partners LLC | E9: 1 | F9: allycompliancepartners.com | G9: joe@allycompliancepartners.com | H9: verified | I9: /in/josephstowell | J9: Londonderry New Hampshire | K9: +1 617-304-0117 | L9: 1 | M9: 5b89436c324d443417b428b7
A10: Boutique compliance | B10: Chris Hardy | C10: Co-Founder | D10: altPILOT Group | E10: 2 | F10: altpilotgroup.com | G10: chris@altpilotgroup.com | H10: verified | I10: /in/chrishardy2 | J10: New York New York | K10: +1 786-473-8090 | L10: 2 | M10: 59399c00a6da9817851bc60b
A11: Boutique compliance | B11: Korrine Kohm | C11: Managing Director | D11: altPILOT Group | E11: 2 | F11: altpilotgroup.com | G11: korrine@altpilotgroup.com | H11: verified | I11: /in/korrine-kohm-816417a | J11: New York New York | K11: +1 786-473-8090 | L11: 2 | M11: 60388f2cec817900010fb78d
A12: Boutique compliance | B12: Eden Turner | C12: Managing Director, Compliance and Risk Management | D12: Asgard Regulatory Group, LLC | E12: 3 | F12: asgardcompliance.com | G12: eturner@asgardcompliance.com | H12: verified | I12: /in/eden-turner-9b08a487 | J12: Oakdale New York | K12: +1 631-801-2900 | L12: 2 | M12: 54a206837468693cdd834906
A13: Boutique compliance | B13: Jon Hurd | C13: Founder, Chief Executive Officer and Certified Anti-Money Laundering Specialist | D13: Asgard Regulatory Group, LLC | E13: 3 | F13: asgardcompliance.com | G13: jhurd@asgardcompliance.com | H13: verified | I13: /in/jonhurdarg | J13: Holbrook New York | K13: +1 631-801-2900 | L13: 2 | M13: 66fe0e657932dd0001e89c77
A14: Boutique compliance | B14: Patrick Kane | C14: Managing Director | D14: Asgard Regulatory Group, LLC | E14: 3 | F14: asgardcompliance.com | G14: pkane@asgardcompliance.com | H14: verified | I14: /in/patrick-kane-7010855 | J14: New York New York | K14: +1 631-801-2900 | L14: 2 | M14: 5acf19dfa6da98d0d0b444d4
A15: Boutique compliance | B15: Jordan Jasser | C15: Partner, President | D15: Aspect Advisors | E15: 6 | F15: aspectadv.com | G15: jordan@aspectadv.com | H15: verified | I15: /in/jordan-jasser-0346b070 | J15: New York New York | K15: +1 415-423-3445 | L15: 2 | M15: 66f6f0e857022d000128cff6
A16: Boutique compliance | B16: Justin Schleifer | C16: President, Co-Founder | D16: Aspect Advisors | E16: 6 | F16: aspectadv.com | G16: justin@aspectadv.com | H16: verified | I16: /in/justin-schleifer-28852036 | J16: New York New York | K16: +1 415-423-3445 | L16: 2 | M16: 66fb2df8518a660001e69ef0
A17: Boutique compliance | B17: Chris Nowak | C17: Founder & CEO | D17: Augmenta Prime | E17: 1 | F17: augmentaprimegroup.com | G17: chris.nowak@augmentaprimegroup.com | H17: verified | I17: /in/chris-nowak-cams-cafp-cbp | J17: New York | L17: 2 | M17: 67183a61bd462b0001c870b7
A18: Boutique compliance | B18: Colleen Kelly | C18: Managing Director | D18: Chenery Compliance Group | E18: 4 | F18: chenerycompliance.com | G18: ckelly@chenerycompliance.com | H18: verified | I18: /in/colleen-kelly-aif%c2%ae-b2088523 | J18: Ashburn Virginia | K18: +1 484-464-0300 | L18: 1 | M18: 60afd5041203cc00014edd51
A19: Boutique compliance | B19: Craig Moreshead | C19: Managing Director | D19: Chenery Compliance Group | E19: 4 | F19: chenerycompliance.com | G19: cmoreshead@chenerycompliance.com | H19: verified | I19: /in/craigmoreshead | J19: West Palm Beach Florida | K19: +1 484-464-0300 | L19: 1 | M19: 54aab3aa7468690630efff13
A20: Boutique compliance | B20: Stefanie Little | C20: Founder & Managing Partner | D20: Chenery Compliance Group | E20: 4 | F20: chenerycompliance.com | G20: slittle@chenerycompliance.com | H20: verified | I20: /in/stefanie-j-little-b155075 | J20: Elkton Maryland | K20: +1 484-464-0300 | L20: 1 | M20: 66fc1f0a3b5eed0001a5e371
A21: Boutique compliance | B21: Thomas Cain | C21: Founder & Managing Partner | D21: Chenery Compliance Group | E21: 4 | F21: chenerycompliance.com | G21: tdecain@chenerygroup.com | H21: verified | I21: /in/tdecain | J21: New York New York | K21: +1 484-464-0300 | L21: 2 | M21: 66f68f29e2b6530001c3b866
A22: Boutique compliance | B22: Claire McCleskey | C22: Co-Founder | D22: Clarity Compliance Consulting | E22: 1 | F22: clarity-consultancy.com | G22: com@clarity-consultancy.com | H22: verified | I22: /in/claire-o-neill-mccleskey | J22: New York New York | L22: 2 | M22: 611a8d85b40c3e0001a54a09
A23: Boutique compliance | B23: David Martin | C23: Founder/CEO | D23: Compliers Consulting Services, LLC | E23: 2 | F23: compliers.com | G23: david@compliers.com | H23: verified | I23: /in/davidjaindlmartin | J23: New York New York | K23: +1 917-345-2461 | L23: 2 | M23: 60cf4bb6becbc70001bd6490
A24: Boutique compliance | B24: Michelle Jacko | C24: CEO | D24: Core Compliance & Legal Services, Inc. | E24: 1 | F24: corecls.com | G24: michelle.jacko@corecls.com | H24: verified | I24: /in/michellejacko | J24: San Diego California | K24: +1 619-278-0020 | L24: 1 | M24: 68cf57da40b35e00013a604e
A25: Boutique compliance | B25: Gary Fox | C25: Managing Director and Partner | D25: DFP Partners | E25: 2 | F25: dfppartners.com | G25: gfox@dfppartners.com | H25: verified | I25: /in/garyfox8 | J25: New York New York | K25: +1 212-751-4422 | L25: 2 | M25: 5fa2428f3770bf0001a19d82
A26: Boutique compliance | B26: Michael Glynn | C26: Principal | D26: DFP Partners | E26: 2 | F26: dfppartners.com | G26: mglynn@sddco.com | H26: verified | I26: /in/michael-glynn-6453575 | J26: New York New York | K26: +1 212-751-4422 | L26: 2 | M26: 5ac982f7a6da9840f6312264
A27: Boutique compliance | B27: Daniel Garcia | C27: Principal Compliance Officer at InnReg | D27: InnReg | E27: 2 | F27: innreg.com | G27: daniel@innreg.com | H27: verified | I27: /in/daniel-garcia-b67a1723 | J27: Fort Lauderdale Florida | K27: +1 305-908-1160 | L27: 2 | M27: 5e7c809a64ba4100017cdb37
A28: Boutique compliance | B28: Francesco Matteini | C28: CEO and Founder | D28: InnReg | E28: 2 | F28: innreg.com | G28: francesco@innreg.com | H28: verified | I28: /in/fmatteini | J28: Miami Florida | K28: +1 305-908-1160 | L28: 2 | M28: 66f438a547af530001b9576b
A29: Boutique compliance | B29: Stephen Murphy | C29: Managing Director | D29: Integrated Compliance Consulting | E29: 2 | F29: integratedcomplianceconsulting.com | G29: smurphy@icc-comply.com | H29: verified | I29: /in/stephen-murphy-cfa-9903874 | L29: 1 | M29: 5fd08a11d173d6000193434a
A30: Boutique compliance | B30: Trish Davis | C30: Managing Director | D30: Integrated Compliance Consulting | E30: 2 | F30: integratedcomplianceconsulting.com | G30: tdavis@integratedcomplianceconsulting.com | H30: verified | I30: /in/trish-davis-4a1668298 | J30: Maize Kansas | L30: 1 | M30: 668cea1a7921f3000181c0e6
A31: Boutique compliance | B31: Jennifer Mascioli-Tudor | C31: Founder and Principal Consultant | D31: JMT Compliance Consulting | E31: 1 | F31: jmtcompliance.com | G31: jennifer@jmtcompliance.com | H31: verified | I31: /in/jennifermascioli | J31: San Francisco California | L31: 1 | M31: 66f11ab66453d300019f27a1
A32: Boutique compliance | B32: Matthew Swendiman | C32: President and Chief Executive Officer | D32: Key Bridge Compliance | E32: 1 | F32: keybridgecompliance.com | G32: mswendiman@keybridgecompliance.com | H32: verified | I32: /in/matthewswendiman | J32: Cincinnati Ohio | K32: +1 859-308-3246 | L32: 1 | M32: 66fd80a967622700018dd038
A33: Boutique compliance | B33: Luisa Franco | C33: CEO & Founder | D33: LFP Risk Solutions | E33: 1 | F33: lfprisksolutions.com | G33: luisa@lfprisksolutions.com | H33: verified | I33: /in/luisafranco1 | J33: New York New York | K33: +1 908-956-3755 | L33: 2 | M33: 66ff99f7ad0d090001ba4d4f
A34: Boutique compliance | B34: Ken Norensberg | C34: Chief Executive Officer | D34: Luxor Financial Group/Broker Dealer/Registered Investment Adviser Experts | E34: 1 | F34: luxorbd.com | G34: ken@luxorbd.com | H34: verified | I34: /in/kennorensberg | J34: New York New York | K34: +1 888-521-8858 | L34: 2 | M34: 55706d89736964704f7d2100
A35: Boutique compliance | B35: Giovanni Corrado | C35: CEO | D35: NextReg | E35: 1 | F35: thenextreg.com | G35: gio@thenextreg.com | H35: verified | I35: /in/giovannicorrado1 | J35: Miami Florida | L35: 2 | M35: 5cf82b27f6512513c23e9949
A36: Boutique compliance | B36: Victoria Hogan | C36: President | D36: NorthPoint Compliance LLC | E36: 1 | F36: npcomply.com | G36: vhogan@npcomply.com | H36: verified | I36: /in/victoria-g-hogan-cfa-331217a | J36: New York New York | K36: +1 732-778-5488 | L36: 2 | M36: 66ec3cbbc381350001a2ac5a
A37: Boutique compliance | B37: Jonathan Saxton | C37: CEO/Founder | D37: Optima Partners | E37: 5 | F37: optima-partners.com | G37: jonathan.saxton@optima-partners.com | H37: verified | I37: /in/jonathan-saxton-12588013 | J37: New York New York | K37: +1 646-205-6380 | L37: 2 | M37: 611c2c1c0a01cc0001072ca7
A38: Boutique compliance | B38: Steve Boyd | C38: Principal | D38: Optima Partners | E38: 5 | F38: optima-partners.com | G38: stephen.boyd@optima-partners.com | H38: verified | I38: /in/steve-b-249a2564 | J38: Miami Florida | K38: +1 646-205-6380 | L38: 2 | M38: 672cdb7d47f6880001bfe6c7
A39: Boutique compliance | B39: Pawneet Abramowski | C39: CEO & Founder | D39: PARC Solutions | E39: 1 | F39: parcsolutionsllc.com | G39: pawneet@parcsolutionsllc.com | H39: verified | I39: /in/pawneet | J39: New York New York | L39: 2 | M39: 67004878fb7271000159de31
A40: Boutique compliance | B40: David Lombardy | C40: Founder and Principal | D40: Pillar Compliance Group | E40: 1 | F40: pillarcompliance.com | G40: dlombardy@pillarcompliance.com | H40: verified | I40: /in/david-lombardy-6472a5 | J40: New York New York | L40: 1 | M40: 54a7c107746869705aa89750
...

Sheet Send List
A1: Tier | B1: Name | C1: Title | D1: Firm | E1: Work email | F1: Email status | G1: LinkedIn profile | H1: Channel | I1: Alternates at firm | J1: Owner | K1: Status | L1: Date contacted | M1: Notes
A2: Boutique compliance | B2: Vick Ekizian | C2: Founder and CEO | D2: 5 Pillars Compliance Consulting, LLC | E2: vick@5pillarscompliance.com | F2: verified | G2: /in/vickekizian | H2: Email | I2: 0
A3: Boutique compliance | B3: Lisa Roitman | C3: Managing Partner | D3: Abide Consulting Group | E3: lisa@abidegrp.com | F3: verified | G3: /in/lisaroitman | H3: Email | I3: 2
A4: Boutique compliance | B4: Robert Masi | C4: Managing Partner | D4: Accordo | E4: robert.masi@accordo.solutions | F4: verified | G4: /in/robert-masi-1a123b8 | H4: Email | I4: 0
A5: Boutique compliance | B5: Stephen Lurie | C5: Principal Owner | D5: Adviser Compliance Consulting | F5: unavailable | G5: /in/stephen-lurie-8b0b371 | H5: LinkedIn only | I5: 1
A6: Boutique compliance | B6: Joseph Stowell | C6: Managing Partner, President | D6: Ally Compliance Partners LLC | E6: joe@allycompliancepartners.com | F6: verified | G6: /in/josephstowell | H6: Email | I6: 0
A7: Boutique compliance | B7: Chris Hardy | C7: Co-Founder | D7: altPILOT Group | E7: chris@altpilotgroup.com | F7: verified | G7: /in/chrishardy2 | H7: Email | I7: 1
A8: Boutique compliance | B8: Jon Hurd | C8: Founder, Chief Executive Officer and Certified Anti-Money Laundering Specialist | D8: Asgard Regulatory Group, LLC | E8: jhurd@asgardcompliance.com | F8: verified | G8: /in/jonhurdarg | H8: Email | I8: 2
A9: Boutique compliance | B9: Justin Schleifer | C9: President, Co-Founder | D9: Aspect Advisors | E9: justin@aspectadv.com | F9: verified | G9: /in/justin-schleifer-28852036 | H9: Email | I9: 5
A10: Boutique compliance | B10: Chris Nowak | C10: Founder & CEO | D10: Augmenta Prime | E10: chris.nowak@augmentaprimegroup.com | F10: verified | G10: /in/chris-nowak-cams-cafp-cbp | H10: Email | I10: 0
A11: Boutique compliance | B11: Stefanie Little | C11: Founder & Managing Partner | D11: Chenery Compliance Group | E11: slittle@chenerycompliance.com | F11: verified | G11: /in/stefanie-j-little-b155075 | H11: Email | I11: 3
A12: Boutique compliance | B12: Claire McCleskey | C12: Co-Founder | D12: Clarity Compliance Consulting | E12: com@clarity-consultancy.com | F12: verified | G12: /in/claire-o-neill-mccleskey | H12: Email | I12: 0
A13: Boutique compliance | B13: David Martin | C13: Founder/CEO | D13: Compliers Consulting Services, LLC | E13: david@compliers.com | F13: verified | G13: /in/davidjaindlmartin | H13: Email | I13: 1
A14: Boutique compliance | B14: Michelle Jacko | C14: CEO | D14: Core Compliance & Legal Services, Inc. | E14: michelle.jacko@corecls.com | F14: verified | G14: /in/michellejacko | H14: Email | I14: 0
A15: Boutique compliance | B15: Gary Fox | C15: Managing Director and Partner | D15: DFP Partners | E15: gfox@dfppartners.com | F15: verified | G15: /in/garyfox8 | H15: Email | I15: 1
A16: Boutique compliance | B16: Francesco Matteini | C16: CEO and Founder | D16: InnReg | E16: francesco@innreg.com | F16: verified | G16: /in/fmatteini | H16: Email | I16: 1
A17: Boutique compliance | B17: Stephen Murphy | C17: Managing Director | D17: Integrated Compliance Consulting | E17: smurphy@icc-comply.com | F17: verified | G17: /in/stephen-murphy-cfa-9903874 | H17: Email | I17: 1
... A27: Boutique compliance | B27: Calvin Robinson | C27: Managing Partner | D27: Quadrant Regulatory Group | E27: crobinson@quadrantregulatory.com | F27: verified | G27: /in/calvinarobinson | H27: Email | I27: 2
A28: Boutique compliance | B28: Gerard Clark | C28: Chief Executive Officer | D28: Regulatory Compliance LLC | F28: unavailable | G28: /in/gerard-clark | H28: LinkedIn only | I28: 0
A29: Boutique compliance | B29: Ivan Barretto | C29: Founder and Managing Director | D29: RIA Compliance Concepts | E29: ivan@riacc.io | F29: verified | G29: /in/ivanbarretto30 | H29: Email | I29: 0
A30: Boutique compliance | B30: Richard Rondano | C30: Managing Partner & Founder | D30: Risk & Compliance Consulting, LLC | F30: unavailable | G30: /in/richardrondano | H30: LinkedIn only | I30: 0
A31: Boutique compliance | B31: Allison Gill | C31: Managing Director | D31: RQC Group | E31: agill@rqcgroup.com | F31: verified | G31: /in/allison-gill-9860734 | H31: Email | I31: 0
A32: Boutique compliance | B32: Janaya Moscony | C32: President | D32: SEC Compliance Consultants, Inc. (SEC3) | E32: janaya@sec3compliance.com | F32: verified | G32: /in/janayasec3 | H32: Email | I32: 0
A33: Boutique compliance | B33: Brian Kesselman | C33: Founder/CRO | D33: Skematic | E33: brian@skematic.com | F33: verified | G33: /in/brian-kesselman | H33: Email | I33: 1
A34: Boutique compliance | B34: Jon Lo | C34: Co-Founder & Managing Director | D34: StrategyBRIX | E34: jon@strategybrix.com | F34: verified | G34: /in/jon-lo-cams | H34: Email | I34: 0
A35: Boutique compliance | B35: Gerald Roop | C35: Principal | D35: Treliant (Acquired by Huron - 2025) | F35: unavailable | G35: /in/gerald-roop-285639b | H35: LinkedIn only | I35: 0
A36: Boutique compliance | B36: Dorothy Dewitt | C36: Founder, CEO | D36: Tölt Strategies | E36: dorothy.dewitt@toltstrategies.com | F36: verified | G36: /in/dorothydewitt | H36: Email | I36: 0
A37: Boutique compliance | B37: Michael Evans | C37: Founder | D37: VEGA Compliance Consulting & Expert Witness | E37: mike.evans@vegacompliance.com | F37: verified | G37: /in/mgevans | H37: Email | I37: 0
A38: Boutique compliance | B38: Joe Paul | C38: Principal and Assurance Practice Leader | D38: Venning | E38: jpaul@venningadvisors.com | F38: verified | G38: /in/josephhpaul | H38: Email | I38: 2
A39: Boutique compliance | B39: Amy Yuter | C39: Managing Principal | D39: Yuter Compliance Consulting | E39: ayuter@yutercompliance.com | F39: verified | G39: /in/amy-yuter-b2284544 | H39: Email | I39: 0
A40: Compliance (national) | B40: Allison Jaffe | C40: Principal and Director of Compliance Programs | D40: 3iCO | E40: ajaffe@3icollc.com | F40: verified | G40: /in/allison-jaffe-3ico | H40: Email | I40: 0
A41: Compliance (national) | B41: Richard Berthy | C41: Chief Executive Officer | D41: ACA Foreside | E41: rberthy@foreside.com | F41: verified | G41: /in/richard-berthy-66812914 | H41: Email | I41: 4
A42: Compliance (national) | B42: Tiffany Ramirez | C42: Founder and Managing Partner | D42: Adviser Solutions Group LLC | F42: unavailable | G42: /in/tiffanylramirez | H42: LinkedIn only | I42: 0
A43: Compliance (national) | B43: Carrie Rinehart-Bekker | C43: Founder, CEO, and Managing Member | D43: Bekker Compliance Consulting Partners, LLC | E43: cbekker@bccp-llc.com | F43: verified | G43: /in/bekkercompliance | H43: Email | I43: 0
A44: Compliance (national) | B44: Dan Denton | C44: Owner | D44: Business Compliance Partners | E44: dan@bizcompliancepartners.com | F44: verified | G44: /in/dan-denton-742a021b | H44: Email | I44: 1
A45: Compliance (national) | B45: Robert Williams | C45: President | D45: Cohasset Associates, Inc. | E45: robert.williams@cohasset.com | F45: verified | G45: /in/robert-f-williams-6227311b | H45: Email | I45: 1
A46: Compliance (national) | B46: Craig Neal | C46: Founder | D46: Compliance Admins LLC | E46: craig.neal@complianceadmins.com | F46: verified | G46: /in/craigneal | H46: Email | I46: 0
A47: Compliance (national) | B47: Alvaro Pereyra | C47: Broker Dealer Chief Executive Officer | D47: Compliance Exchange Group (CXG) | E47: apereyra@cxgllc.com | F47: verified | G47: /in/alvaro-pereyra-7503a18 | H47: Email | I47: 1
A48: Compliance (national) | B48: Mitch Avnet | C48: Managing Partner | D48: Compliance Risk Concepts (CRC​) | E48: mavnet@compliance-risk.com | F48: verified | G48: /in/mitchavnet | H48: Email | I48: 3
A49: Compliance (national) | B49: Peter Guarino | C49: President / Chief Compliance Officer | D49: Compliance4 | E49: pguarino@compliance4.com | F49: verified | G49: /in/peterguarino | H49: Email | I49: 0
...
